Workbook

Sheet Febrero
B1: ESTADO DE POZOS - FEBRERO 2024 | J1: 45292 | M1: 45292
B2: *PFORMACION | C2: *ESTADO | D2: *TIPO_DE_POZO | E2: *ULT_EST | F2: *BATERIA | G2: *ULT_EST Enero | J2: Count of *PFORMACION | M2: Count of *PFORMACION
B3: AA3 | C3: DPA | D3: SECO | E3: DPAPET | F3: ABAND. | G3: =IFERROR(VLOOKUP(B3,Enero!$B$2:$G$5822,4,0),"") -> DPAPET | J3: *ULT_EST | K3: Total | M3: *ULT_EST | N3: Total | R3: Total
B4: AA11 | C4: BM | D4: BM | E4: BM | F4: CA 19 | G4: =IFERROR(VLOOKUP(B4,Enero!$B$2:$G$5822,4,0),"") -> BM | J4: ACTINYA | K4: 50 | M4: ACTINYA | N4: 50 | O4: =+K4-N4 -> 0 | R4: 50 | S4: =+K4-R4 -> 0
B5: AA16 | C5: ATA | D5: CT | E5: ATAPET | F5: ATA | G5: =IFERROR(VLOOKUP(B5,Enero!$B$2:$G$5822,4,0),"") -> ATAPET | J5: ACTPETF | K5: 179 | M5: ACTPETF | N5: 183 | O5: =+K5-N5 -> -4 | R5: 181 | S5: =+K5-R5 -> -2
B6: AA25 | C6: PETS | D6: SUABTBG | E6: ACTPETS | F6: SWAB | G6: =IFERROR(VLOOKUP(B6,Enero!$B$2:$G$5822,4,0),"") -> ACTPETS | J6: ACTPETS | K6: 499 | M6: ACTPETS | N6: 504 | O6: =+K6-N6 -> -5 | R6: 502 | S6: =+K6-R6 -> -3
B7: AA26 | C7: DPA | D7: SECO | E7: DPAPET | F7: ABAND. | G7: =IFERROR(VLOOKUP(B7,Enero!$B$2:$G$5822,4,0),"") -> DPAPET | J7: APA_CNPC | K7: 158 | M7: APA_CNPC | N7: 130 | O7: =+K7-N7 -> 28 | R7: 158 | S7: =+K7-R7 -> 0
B8: AA27 | C8: PETF | D8: SUABCSG | E8: ACTPETF | F8: SWAB | G8: =IFERROR(VLOOKUP(B8,Enero!$B$2:$G$5822,4,0),"") -> ACTPETF | J8: APA_PB | K8: 14 | M8: APA_PB | N8: 14 | O8: =+K8-N8 -> 0 | R8: 14 | S8: =+K8-R8 -> 0
B9: AA28 | C9: APA | D9: A | E9: APA_PC | F9: ABAND. | G9: =IFERROR(VLOOKUP(B9,Enero!$B$2:$G$5822,4,0),"") -> APA_PC | J9: APA_PC | K9: 1013 | M9: APA_PC | N9: 1013 | O9: =+K9-N9 -> 0 | R9: 1013 | S9: =+K9-R9 -> 0
B10: AA35 | C10: ATA | D10: CT | E10: ATAPET | F10: ATA | G10: =IFERROR(VLOOKUP(B10,Enero!$B$2:$G$5822,4,0),"") -> ATAPET | J10: APAPET | K10: 290 | M10: APAPET | N10: 290 | O10: =+K10-N10 -> 0 | R10: 290 | S10: =+K10-R10 -> 0
B11: AA36 | C11: APA | D11: A | E11: APAPET | F11: ABAND. | G11: =IFERROR(VLOOKUP(B11,Enero!$B$2:$G$5822,4,0),"") -> APAPET | J11: ATAGAS | K11: 4 | M11: ATAGAS | N11: 6 | O11: =+K11-N11 -> -2 | R11: 4 | S11: =+K11-R11 -> 0
B12: AA37 | C12: CM | D12: CM | E12: INACTPETF | F12: SWAB | G12: =IFERROR(VLOOKUP(B12,Enero!$B$2:$G$5822,4,0),"") -> INACTPETF | J12: ATAINY | K12: 11 | M12: ATAINY | N12: 13 | O12: =+K12-N12 -> -2 | R12: 11 | S12: =+K12-R12 -> 0
B13: AA39 | C13: PETF | D13: SUABCSG | E13: ACTPETF | F13: SWAB | G13: =IFERROR(VLOOKUP(B13,Enero!$B$2:$G$5822,4,0),"") -> ACTPETF | J13: ATAPET | K13: 498 | M13: ATAPET | N13: 521 | O13: =+K13-N13 -> -23 | R13: 498 | S13: =+K13-R13 -> 0
B14: AA40 | C14: ATA | D14: CT | E14: ATAPET | F14: ATA | G14: =IFERROR(VLOOKUP(B14,Enero!$B$2:$G$5822,4,0),"") -> ATAPET | J14: BCP | K14: 9 | M14: BCP | N14: 10 | O14: =+K14-N14 -> -1 | R14: 9 | S14: =+K14-R14 -> 0
B15: AA41 | C15: DPA | D15: SECO | E15: DPAPET | F15: ABAND. | G15: =IFERROR(VLOOKUP(B15,Enero!$B$2:$G$5822,4,0),"") -> DPAPET | J15: BM | K15: 2217 | M15: BM | N15: 2251 | O15: =+K15-N15 -> -34 | R15: 2218 | S15: =+K15-R15 -> -1
... B30: AA58 | C30: BM | D30: BM | E30: BM | F30: CA 19 | G30: =IFERROR(VLOOKUP(B30,Enero!$B$2:$G$5822,4,0),"") -> BM | J30: Total general | K30: 5820 | M30: Total general | N30: 5820 | O30: =+K30-N30 -> 0 | R30: 5820 | S30: =+K30-R30 -> 0
B31: AA60 | C31: DPA | D31: SECO | E31: DPAPET | F31: ABAND. | G31: =IFERROR(VLOOKUP(B31,Enero!$B$2:$G$5822,4,0),"") -> DPAPET
B32: AA61 | C32: BM | D32: BM | E32: BM | F32: CA 19 | G32: =IFERROR(VLOOKUP(B32,Enero!$B$2:$G$5822,4,0),"") -> BM
B33: AA62 | C33: APA | D33: A | E33: APA_CNPC | F33: ABAND. | G33: =IFERROR(VLOOKUP(B33,Enero!$B$2:$G$5822,4,0),"") -> APA_CNPC
B34: AA63 | C34: ATA | D34: CT | E34: ATAPET | F34: ATA | G34: =IFERROR(VLOOKUP(B34,Enero!$B$2:$G$5822,4,0),"") -> ATAPET
B35: AA64 | C35: PETS | D35: SUABTBG | E35: ACTPETS | F35: SWAB | G35: =IFERROR(VLOOKUP(B35,Enero!$B$2:$G$5822,4,0),"") -> ACTPETS
B36: AA65 | C36: ATA | D36: CT | E36: ATAPET | F36: ATA | G36: =IFERROR(VLOOKUP(B36,Enero!$B$2:$G$5822,4,0),"") -> ATAPET
B37: AA66 | C37: ATA | D37: CT | E37: ATAPET | F37: ATA | G37: =IFERROR(VLOOKUP(B37,Enero!$B$2:$G$5822,4,0),"") -> ATAPET
B38: AA68 | C38: PETS | D38: SUABTBG | E38: ACTPETS | F38: SWAB | G38: =IFERROR(VLOOKUP(B38,Enero!$B$2:$G$5822,4,0),"") -> ACTPETS
B39: AA70 | C39: BM | D39: BM | E39: BM | F39: CA 19 | G39: =IFERROR(VLOOKUP(B39,Enero!$B$2:$G$5822,4,0),"") -> BM
B40: AA71 | C40: CM | D40: CM | E40: INACTBM | F40: CA 19 | G40: =IFERROR(VLOOKUP(B40,Enero!$B$2:$G$5822,4,0),"") -> INACTBM
B41: AA72 | C41: BM | D41: BM | E41: BM | F41: CA 19 | G41: =IFERROR(VLOOKUP(B41,Enero!$B$2:$G$5822,4,0),"") -> BM
B42: AA76 | C42: CM | D42: CM | E42: INACTPETF | F42: SWAB | G42: =IFERROR(VLOOKUP(B42,Enero!$B$2:$G$5822,4,0),"") -> INACTPETF
... B5822: PTE-10 | C5822: ATA | D5822: CT | E5822: ATAPET | F5822: ATA | G5822: =IFERROR(VLOOKUP(B5822,Enero!$B$2:$G$5822,4,0),"") -> ATAPET

Sheet Enero
B1: ESTADO DE POZOS - ENERO 2024 | J1: 45292 | M1: 45261
B2: *PFORMACION | C2: *ESTADO | D2: *TIPO_DE_POZO | E2: *ULT_EST | F2: *BATERIA | G2: *ULT_EST Diciembre | J2: Count of *PFORMACION | M2: Count of *PFORMACION
B3: AA3 | C3: DPA | D3: SECO | E3: DPAPET | F3: ABAND. | G3: DPAPET | J3: *ULT_EST | K3: Total | M3: *ULT_EST | N3: Total
B4: AA11 | C4: BM | D4: BM | E4: BM | F4: CA 19 | G4: BM | J4: ACTINYA | K4: 50 | M4: ACTINYA | N4: 50 | O4: =+K4-N4 -> 0
B5: AA16 | C5: ATA | D5: CT | E5: ATAPET | F5: ATA | G5: ATAPET | J5: ACTPETF | K5: 183 | M5: ACTPETF | N5: 179 | O5: =+K5-N5 -> 4
B6: AA25 | C6: PETS | D6: SUABTBG | E6: ACTPETS | F6: SWAB | G6: ACTPETS | J6: ACTPETS | K6: 504 | M6: ACTPETS | N6: 504 | O6: =+K6-N6 -> 0 | S6: =+GETPIVOTDATA("*PFORMACION",$J$2,"*ULT_EST","ACTPETF")+GETPIVOTDATA("*PFORMACION",$J$2,"*ULT_EST","ACTPETS") -> 687 | T6: =+N6+N7 -> 608
B7: AA26 | C7: DPA | D7: SECO | E7: DPAPET | F7: ABAND. | G7: DPAPET | J7: APA_CNPC | K7: 130 | M7: APA_CNPC | N7: 104 | O7: =+K7-N7 -> 26 | S7: =+GETPIVOTDATA("*PFORMACION",$J$2,"*ULT_EST","INACTPETF")+GETPIVOTDATA("*PFORMACION",$J$2,"*ULT_EST","INACTPETS") -> 164 | T7: =+N27+N28 -> 123
B8: AA27 | C8: PETF | D8: SUABCSG | E8: ACTPETF | F8: SWAB | G8: ACTPETF | J8: APA_PB | K8: 14 | M8: APA_PB | N8: 14 | O8: =+K8-N8 -> 0 | S8: =+S7+S6 -> 851 | T8: =+T7+T6 -> 731
B9: AA28 | C9: APA | D9: A | E9: APA_PC | F9: ABAND. | G9: APA_PC | J9: APA_PC | K9: 1013 | M9: APA_PC | N9: 1013 | O9: =+K9-N9 -> 0
B10: AA35 | C10: ATA | D10: CT | E10: ATAPET | F10: ATA | G10: ATAPET | J10: APAPET | K10: 290 | M10: APAPET | N10: 290 | O10: =+K10-N10 -> 0
B11: AA36 | C11: APA | D11: A | E11: APAPET | F11: ABAND. | G11: APAPET | J11: ATAGAS | K11: 6 | M11: ATAGAS | N11: 9 | O11: =+K11-N11 -> -3
B12: AA37 | C12: CM | D12: CM | E12: INACTPETF | F12: SWAB | G12: INACTPETF | J12: ATAINY | K12: 13 | M12: ATAINY | N12: 16 | O12: =+K12-N12 -> -3
B13: AA39 | C13: PETF | D13: SUABCSG | E13: ACTPETF | F13: SWAB | G13: ACTPETF | J13: ATAPET | K13: 521 | M13: ATAPET | N13: 539 | O13: =+K13-N13 -> -18
B14: AA40 | C14: ATA | D14: CT | E14: ATAPET | F14: ATA | G14: ATAPET | J14: BCP | K14: 10 | M14: BCP | N14: 11 | O14: =+K14-N14 -> -1
B15: AA41 | C15: DPA | D15: SECO | E15: DPAPET | F15: ABAND. | G15: DPAPET | J15: BM | K15: 2251 | M15: BM | N15: 2281 | O15: =+K15-N15 -> -30
B16: AA42 | C16: DPA | D16: SECO | E16: DPAPET | F16: ABAND. | G16: DPAPET | J16: BO | K16: 20 | M16: BO | N16: 20 | O16: =+K16-N16 -> 0
B17: AA43 | C17: ATA | D17: CT | E17: ATAPET | F17: ATA | G17: ATAPET | J17: DPAPET | K17: 209 | M17: DPAPET | N17: 209 | O17: =+K17-N17 -> 0
B18: AA44 | C18: ATA | D18: CT | E18: ATAPET | F18: ATA | G18: ATAPET | J18: GL | K18: 1 | M18: GL | N18: 1 | O18: =+K18-N18 -> 0
B19: AA45 | C19: ATA | D19: CT | E19: ATAPET | F19: ATA | G19: ATAPET | J19: INACTBCP | K19: 4 | M19: INACTBCP | N19: 3 | O19: =+K19-N19 -> 1
B20: AA46 | C20: ATA | D20: CT | E20: ATAPET | F20: ATA | G20: ATAPET | J20: INACTBM | K20: 298 | M20: INACTBM | N20: 269 | O20: =+K20-N20 -> 29 | S20: =+GETPIVOTDATA("*PFORMACION",$J$2,"*ULT_EST","BM")+GETPIVOTDATA("*PFORMACION",$J$2,"*ULT_EST","INACTBM") -> 2549 | T20: =+N16+N21 -> 21
B21: AA47 | C21: BM | D21: BM | E21: BM | F21: CA 19 | G21: BM | J21: INACTBO | K21: 1 | M21: INACTBO | N21: 1 | O21: =+K21-N21 -> 0
B22: AA48 | C22: BM | D22: BM | E22: BM | F22: CA 19 | G22: BM | J22: INACTGAS | K22: 16 | M22: INACTGAS | N22: 16 | O22: =+K22-N22 -> 0
B23: AA49 | C23: ATA | D23: CT | E23: ATAPET | F23: ATA | G23: ATAPET | J23: INACTGL | K23: 3 | M23: INACTGL | N23: 3 | O23: =+K23-N23 -> 0
B24: AA50 | C24: BM | D24: BM | E24: BM | F24: CA 19 | G24: BM | J24: INACTINYA | K24: 37 | M24: INACTINYA | N24: 37 | O24: =+K24-N24 -> 0
B25: AA51 | C25: PETF | D25: SUABCSG | E25: ACTPETF | F25: SWAB | G25: ACTPETF | J25: INACTINYG | K25: 6 | M25: INACTINYG | N25: 6 | O25: =+K25-N25 -> 0
B26: AA52 | C26: APA | D26: A | E26: APA_CNPC | F26: ABAND. | G26: ATAPET | J26: INACTPETF | K26: 57 | M26: INACTPETF | N26: 62 | O26: =+K26-N26 -> -5
B27: AA53 | C27: PETS | D27: SUABTBG | E27: ACTPETS | F27: SWAB | G27: ACTPETS | J27: INACTPETS | K27: 107 | M27: INACTPETS | N27: 107 | O27: =+K27-N27 -> 0
B28: AA54 | C28: CM | D28: CM | E28: INACTPETF | F28: SWAB | G28: INACTPETF | J28: INACTPL | K28: 16 | M28: INACTPL | N28: 16 | O28: =+K28-N28 -> 0
B29: AA56 | C29: DPA | D29: SECO | E29: DPAPET | F29: ABAND. | G29: DPAPET | J29: PL | K29: 60 | M29: PL | N29: 60 | O29: =+K29-N29 -> 0
B30: AA58 | C30: BM | D30: BM | E30: BM | F30: CA 19 | G30: BM | J30: Total general | K30: 5820 | M30: Total general | N30: 5820 | O30: =+K30-N30 -> 0
B31: AA60 | C31: DPA | D31: SECO | E31: DPAPET | F31: ABAND. | G31: DPAPET
B32: AA61 | C32: BM | D32: BM | E32: BM | F32: CA 19 | G32: BM
B33: AA62 | C33: APA | D33: A | E33: APA_CNPC | F33: ABAND. | G33: ATAPET
B34: AA63 | C34: ATA | D34: CT | E34: ATAPET | F34: ATA | G34: ATAPET
B35: AA64 | C35: PETS | D35: SUABTBG | E35: ACTPETS | F35: SWAB | G35: ACTPETS
B36: AA65 | C36: ATA | D36: CT | E36: ATAPET | F36: ATA | G36: ATAPET
B37: AA66 | C37: ATA | D37: CT | E37: ATAPET | F37: ATA | G37: ATAPET
B38: AA68 | C38: PETS | D38: SUABTBG | E38: ACTPETS | F38: SWAB | G38: ACTPETS
B39: AA70 | C39: BM | D39: BM | E39: BM | F39: CA 19 | G39: BM
B40: AA71 | C40: CM | D40: CM | E40: INACTBM | F40: CA 19 | G40: INACTBM
...
